Workbook

Sheet Data_Vintage
A1: Мэдээллийн он сар (Data vintage) — тайлант үе 2026-07
A2: Which month each source actually carries. CURRENT = the reported month. LAGGED = the source has not published the reported month yet, so the PREVIOUS month's figure is shown and the period column says which. Nothing is ever extrapolated or carried forward silently.
A4: Эх сурвалж (Source) | B4: Хаана орсон (Feeds) | C4: Аль сарынх (Period of the data) | D4: Төлөв (Status) | E4: Тайлбар (Note)
A5: Customs (gaali.mn) | B5: Trade, Commodities, Border prices, Trade_Sections | C5: 2026-07 | D5: CURRENT | E5: monthly bulletin for the reported month
A6: NSO national accounts | B6: GDP_Growth, GDP_Sectors | C6: 2026-Q2 | D6: QUARTERLY | E6: quarterly series — the latest quarter ending on or before the reported month
A7: Эдийн засгийн сарын өсөлт (NSO monthly GDP growth) | B7: GDP_Growth — monthly growth and sector contributions | C7: 2026-05 | D7: LAGGED | E7: WARNING: MIEG newest period is 2026-05, target is 2026-07
A8: Mongolbank bulletin | B8: Inflation, policy rate, budget, FX | C8: 2026-07 | D8: CURRENT | E8: issue mongolbank_bulletin.xlsx
A9: Bank balance sheet | B9: Banking (assets, loans, NPL, equity) | C9: 2026-07 | D9: CURRENT | E9: latest column in the report: 2026.07.31
A10: Deposit tree | B10: Banking (харилцах, хадгаламж) | C10: 2026-07 | D10: CURRENT | E10: source: deposits_export.json, 19 period column(s)
A11: Bank loan report | B11: Loan_Detail (bridge, sectors, NPL, rates) | C11: 2026-07 | D11: CURRENT | E11: monthly flow statement
A12: Balance of payments | B12: External_Sector (BoP detail) | C12: 2026-06 | D12: LAGGED | E12: BoP export reaches month 6 only; these are cumulative I-6 figures, not I-7.
A13: NSO Худалдааны салбарын нийт б | B13: Real_Sector — trade | C13: 2026-06 | D13: LAGGED | E13: M, 5 components
A14: NSO Зочид буудлын салбарын орл | B14: Real_Sector — hotel | C14: 2026-06 | D14: LAGGED | E14: M, 5 components
A15: NSO Нийтийн хоолны салбарын ор | B15: Real_Sector — food | C15: 2026-06 | D15: LAGGED | E15: M, 5 components
... A20: Mongolbank cards | B20: External_Sector (reserves, FDI, debt) | C20: see card dates | D20: PER-CARD | E20: each card carries its own 'as of' date: 2026 оны 1-р улирал, 2026 оны 6-р сар, 2026 оны 7-р сар, 2026 оны 7-р сарын байдлаар
A22: АНХААР (read before using): Эдийн засгийн сарын өсөлт (NSO monthly GDP growth) is 2026-05, not 2026-07; Balance of payments is 2026-06, not 2026-07; NSO Худалдааны салбарын нийт б is 2026-06, not 2026-07; NSO Зочид буудлын салбарын орл is 2026-06, not 2026-07; NSO Нийтийн хоолны салбарын ор is 2026-06, not 2026-07

Sheet Summary
A1: Macroeconomic KPI Summary — 2026 оны 7-р сар
A2: Green figures are live links to the data sheets. Feeds deck slide 3 and headline text on slides 4, 6, 9, 12, 13.
A4: МЭДЭЭЛЛИЙН ОН САР / DATA AS OF: энэ хуудас олон эх сурвалжийг нэгтгэнэ (this sheet mixes sources). ӨМНӨХ САРЫНХ / previous month: Эдийн засгийн сарын өсөлт (NSO monthly GDP growth) = 2026-05; Balance of payments = 2026-06; NSO Худалдааны салбарын нийт б = 2026-06; NSO Зочид буудлын салбарын орл = 2026-06; NSO Нийтийн хоолны салбарын ор = 2026-06 — дэлгэрэнгүйг Data_Vintage хуудаснаас (see Data_Vintage)
A6: Үзүүлэлт (Indicator) | B6: Утга (Value) | C6: Нэгж (Unit) | D6: Period / note | E6: Source | F6: Deck slide
A7: Бодит ДНБ-ий өсөлт (Real GDP growth, YoY cum.) | B7: =GDP_Growth!C60 | C7: % | D7: 2026-Q2 | E7: NSO 1212.mn | F7: 3, 4
A8: Эдийн засгийн өсөлтийн сарын индикатор (MIEG, YoY cum.) | B8: 0.0732 | C8: % | D8: WARNING: MIEG newest period is 2026-05, target is 2026-07 | E8: NSO 1212.mn | F8: 4
A9: Инфляц (Inflation, headline) | B9: 0.13 | C9: % | D9: Mongolbank bulletin, 2026 оны 7-р сарын байдлаар | E9: MB bulletin | F9: 3, 6
A10: Инфляцын зорилтот түвшин (Inflation target) | B10: 0.08 | C10: % | D10: Mongolbank official target | E10: Mongolbank | F10: 6
A11: Бодлогын хүү (Policy rate) | B11: 0.12 | C11: % | D11: MB bulletin, Rate sheet | E11: Mongolbank | F11: 3, 8
A12: Зээлийн хүү (Bank loan rate, new loans) | B12: 0.174 | C12: % | D12: 2026 оны 7-р сар | E12: Mongolbank | F12: 8
A13: Хадгаламжийн хүү (Deposit rate, new deposits) | B13: 0.114 | C13: % | D13: 2026 оны 7-р сар | E13: Mongolbank | F13: 8
A14: Банкны салбарын зээл (Bank loans outstanding) | B14: 47.9 | C14: level | D14: tln MNT, 2026 оны 7-р сар | E14: Mongolbank | F14: 16
A15: Ипотекийн зээл (Mortgage loans outstanding) | B15: 12.4 | C15: level | D15: tln MNT, 2026 оны 7-р сар | E15: Mongolbank | F15: 16
A16: Нийт экспорт (Total export) | B16: =Trade!C7 | C16: level | D16: thous. USD, 2026 оны 7-р сарын байдлаар | E16: Customs gaali.mn | F16: 9
A17: Нийт импорт (Total import) | B17: =Trade!C8 | C17: level | D17: thous. USD, 2026 оны 7-р сарын байдлаар | E17: Customs gaali.mn | F17: 9
A18: Худалдааны тэнцэл (Trade balance) | B18: =Trade!C7-Trade!C8 | C18: level | D18: thous. USD; formula: export cell - import cell | E18: Customs gaali.mn | F18: 9
A19: Экспортын өсөлт (Export growth, YoY) | B19: =IFERROR(Trade!C7/Trade!B7-1,"") | C19: % | D19: formula: current / previous - 1 | E19: Customs gaali.mn | F19: 9
A20: Импортын өсөлт (Import growth, YoY) | B20: =IFERROR(Trade!C8/Trade!B8-1,"") | C20: % | D20: formula: current / previous - 1 | E20: Customs gaali.mn | F20: 9
A21: Худалдааны тэнцэл, өмнөх оны эсрэг (Trade balance vs prev yr) | B21: =IFERROR(Trade!C9/Trade!B9,"") | C21: x | D21: balance multiple | E21: Customs gaali.mn | F21: 9
A22: Нүүрсний экспортын хэмжээ (Coal export volume) | B22: =IFERROR(Commodities!D7/1E9,"") | C22: level | D22: mln t | E22: Customs gaali.mn | F22: 10, 13
A23: Нүүрсний хэмжээний өсөлт (Coal volume growth, YoY) | B23: =IFERROR(Commodities!D7/Commodities!C7-1,"") | C23: % | D23: formula over quantity cells | E23: Customs gaali.mn | F23: 10
A24: Зэсийн баяжмалын экспортын хэмжээ (Copper conc. export volume) | B24: =IFERROR(Commodities!D8/1E6,"") | C24: level | D24: thous. t | E24: Customs gaali.mn | F24: 10
A25: Зэсийн хэмжээний өсөлт (Copper volume growth, YoY) | B25: =IFERROR(Commodities!D8/Commodities!C8-1,"") | C25: % | D25: formula over quantity cells | E25: Customs gaali.mn | F25: 10
A26: Алтны экспортын хэмжээ (Gold export volume) | B26: =Commodities!D9 | C26: level | D26: kg | E26: Customs gaali.mn | F26: 10
A27: Алтны хэмжээний өсөлт (Gold volume growth, YoY) | B27: =IFERROR(Commodities!D9/Commodities!C9-1,"") | C27: % | D27: formula over quantity cells | E27: Customs gaali.mn | F27: 10
A28: Гадаад валютын нөөц (FX reserves) | B28: 7963 | C28: level | D28: mln USD, 2026 оны 7-р сар | E28: Mongolbank | F28: 3, 12
A29: Төлбөрийн тэнцэл (Balance of payments) | B29: 567 | C29: level | D29: mln USD, 2026 оны 6-р сар | E29: Mongolbank | F29: 12
A30: Нийт гадаад өр (External debt) | B30: 40218 | C30: level | D30: mln USD, 2026 оны 1-р улирал | E30: Mongolbank | F30: 12
A31: ШХО-ын үлдэгдэл (FDI stock) | B31: 37509 | C31: level | D31: mln USD, 2026 оны 1-р улирал | E31: Mongolbank | F31: 12
A32: Ам.долларын ханш (USD/MNT rate, eop) | B32: 3592.73 | C32: level | D32: YoY 0.1%, MB bulletin Exchange rate sheet | E32: MB bulletin | F32: 3
A33: Банкны нийт зээлийн өсөлт (DC loans growth, YoY) | B33: 0.13 | C33: % | D33: loans outstanding 48.19 tln ₮ | E33: MB bulletin | F33: 16
A34: Иргэдийн зээлийн өсөлт (Individuals' loans growth, YoY) | B34: 0.121 | C34: % | D34: individuals 26.65 tln ₮ | E34: MB bulletin | F34: 16
A35: Банкны нийт актив (Bank total assets) | B35: =IFERROR(Banking!C7/1E6,"") | C35: level | D35: tln MNT, as of 2026.07.31 | E35: Mongolbank | F35: 16
A36: Чанаргүй зээлийн өөрчлөлт (Bank NPL change since Jan) | B36: =IFERROR(Banking!C12/Banking!B12-1,"") | C36: % | D36: change measured 2025.07.31 -> 2026.07.31 (earliest column in the report; not necessarily 31 Dec) | E36: Mongolbank | F36: 16
A37: Төсвийн тэнцэл (Budget balance, cum.) | B37: -2206.4 | C37: level | D37: bln MNT, 2026 оны 7-р сарын байдлаар | E37: MB bulletin | F37: 13
A38: Төсвийн орлого, гүйцэтгэл (Budget revenue collected) | B38: 19829.8 | C38: level | D38: bln MNT | E38: MB bulletin | F38: 13

Sheet GDP_Growth
A1: Real GDP (2015 prices) — levels & growth
A2: Deck slide 4. Source datapoints: NSO National Accounts (DT_NSO_0500_004V1). All growth figures are formulas over the quarterly levels below.
A4: МЭДЭЭЛЛИЙН ОН САР / DATA AS OF: NSO national accounts — 2026-Q2 (QUARTERLY) [тайлант үе / reported month: 2026-07]
A6: Улирлын бодит ДНБ (Quarterly real GDP levels, mln MNT, 2015 prices)
A7: Он (Year) | B7: Улирал (Quarter) | C7: Бодит ДНБ (Real GDP, 2015p) | D7: Жилийн өсөлт (YoY growth)
A8: 2015 | B8: 1 | C8: 4193640.8
A9: 2015 | B9: 2 | C9: 6296039.6
A10: 2015 | B10: 3 | C10: 6303713.8
A11: 2015 | B11: 4 | C11: 6101386.7
A12: 2016 | B12: 1 | C12: 4302469.6 | D12: =IFERROR(C12/C8-1,"")
A13: 2016 | B13: 2 | C13: 6353504.7 | D13: =IFERROR(C13/C9-1,"")
A14: 2016 | B14: 3 | C14: 5990073.9 | D14: =IFERROR(C14/C10-1,"")
A15: 2016 | B15: 4 | C15: 6589815.6 | D15: =IFERROR(C15/C11-1,"")
A16: 2017 | B16: 1 | C16: 4550537.5 | D16: =IFERROR(C16/C12-1,"")
A17: 2017 | B17: 2 | C17: 6731828.3 | D17: =IFERROR(C17/C13-1,"")
A18: 2017 | B18: 3 | C18: 6388502.9 | D18: =IFERROR(C18/C14-1,"")
A19: 2017 | B19: 4 | C19: 6874772 | D19: =IFERROR(C19/C15-1,"")
A20: 2018 | B20: 1 | C20: 4836449.6 | D20: =IFERROR(C20/C16-1,"")
A21: 2018 | B21: 2 | C21: 7225676.3 | D21: =IFERROR(C21/C17-1,"")
A22: 2018 | B22: 3 | C22: 6841775.1 | D22: =IFERROR(C22/C18-1,"")
A23: 2018 | B23: 4 | C23: 7542770.3 | D23: =IFERROR(C23/C19-1,"")
... A53: 2026 | B53: 2 | C53: 9692115 | D53: =IFERROR(C53/C49-1,"")
A56: Өссөн дүнгээрх өсөлт (Cumulative growth by period = SUM of quarters vs same quarters a year earlier)
A57: Он (Year) | B57: I-III | C57: I-VI | D57: I-IX | E57: I-XII
A58: 2024 | B58: =IFERROR(SUM(C44:C44)/SUM(C40:C40)-1,"") | C58: =IFERROR(SUM(C44:C45)/SUM(C40:C41)-1,"") | D58: =IFERROR(SUM(C44:C46)/SUM(C40:C42)-1,"") | E58: =IFERROR(SUM(C44:C47)/SUM(C40:C43)-1,"")
A59: 2025 | B59: =IFERROR(SUM(C48:C48)/SUM(C44:C44)-1,"") | C59: =IFERROR(SUM(C48:C49)/SUM(C44:C45)-1,"") | D59: =IFERROR(SUM(C48:C50)/SUM(C44:C46)-1,"") | E59: =IFERROR(SUM(C48:C51)/SUM(C44:C47)-1,"")
A60: 2026 | B60: =IFERROR(SUM(C52:C52)/SUM(C48:C48)-1,"") | C60: =IFERROR(SUM(C52:C53)/SUM(C48:C49)-1,"")
A63: Эдийн засгийн өсөлтийн сарын индикатор (MIEG, cumulative YoY, NSO DT_NSO_0500_001V5)
A64: Сар (Month) | B64: Өсөлт (Growth, YoY cum.)
A65: 2016-01 | B65: 0.0274
A66: 2016-02 | B66: 0.0336
A67: 2016-03 | B67: 0.026
A68: 2016-04 | B68: 0.0256
A69: 2016-05 | B69: 0.0251
A70: 2016-06 | B70: 0.0158
A71: 2016-07 | B71: 0.0055
A72: 2016-08 | B72: 0.0004
A73: 2016-09 | B73: -0.0088
A74: 2016-10 | B74: 0.0001
A75: 2016-11 | B75: 0.0097
...

Sheet GDP_Sectors
A1: Sector contributions to real GDP growth (pp)
A2: Deck slide 5. Contribution = Δsector real value added / prior-period total GDP (computed upstream from NSO levels). Total row is a SUM formula and must equal GDP growth.
A4: МЭДЭЭЛЛИЙН ОН САР / DATA AS OF: NSO national accounts — 2026-Q2 (QUARTERLY) [тайлант үе / reported month: 2026-07]
A6: Салбар (Sector) | B6: 2025 (I-XII) | C6: 2026 (I-VI)
A7: Хөдөө аж ахуй, ойн аж ахуй, загас барилт, ан агнуур (Agriculture, forestry, fishing & hunting) | B7: 2.86 | C7: 1.45
A8: Уул уурхай, олборлолт (Mining & quarrying) | B8: 1.41 | C8: 3.91
A9: Боловсруулах үйлдвэрлэл (Manufacturing) | B9: 0.74 | C9: 0.07
A10: Цахилгаан, хий, уур, агааржуулалт (Electricity, gas, steam & air conditioning) | B10: 0.25 | C10: 0.23
A11: Барилга (Construction) | B11: 0.52 | C11: 0.16
A12: Бөөний болон жижиглэн худалдаа, машин, мотоциклийн засвар, үйлчилгээ (Wholesale & retail trade; vehicle repair) | B12: -0.55 | C12: -0.02
A13: Тээвэр ба агуулахын үйл ажиллагаа (Transportation & storage) | B13: 0.31 | C13: 0.82
A14: Мэдээлэл, холбоо (Information & communication) | B14: 0.24 | C14: 0.25
A15: Үйлчилгээний бусад үйл ажиллагаа (Other service activities) | B15: 1.03 | C15: 0.76
A16: Бүтээгдэхүүний цэвэр татвар (Net taxes on products) | B16: 0.04 | C16: 0.05
A17: Нийт (Total = GDP growth, pp) | B17: =SUM(B7:B16) | C17: =SUM(C7:C16)

Sheet Inflation
A1: Inflation
A2: Deck slides 6-7. Headline from the Mongolbank statistical bulletin; the 12-month CPI series requires the NSO CPI table id (see raw_ingestor.py NSO_TABLES). Values stored as fractions, shown as % via number format.
A4: МЭДЭЭЛЛИЙН ОН САР / DATA AS OF: Mongolbank bulletin — 2026-07 (CURRENT) [тайлант үе / reported month: 2026-07]
A6: Үзүүлэлт (Indicator) | B6: Утга (Value) | C6: Note
A7: Инфляц (Headline inflation, YoY) | B7: 0.13 | C7: Mongolbank bulletin (mongolbank_bulletin.xlsx, period 2026-07)
A8: Монголбанкны зорилт (Mongolbank target) | B8: 0.08 | C8: official target
A9: Зорилтоос зөрүү (Gap vs target) | B9: =B7-B8 | C9: formula: headline - target; positive = above target
A10: Махны хувь нэмэр (Meat contribution) | B10: n/a | C10: pp of headline, when stated in the source
A11: Бодлогын хүү (Policy rate) | B11: 0.12 | C11: MB bulletin, Rate sheet
A12: Махны үнийн өсөлт (Meat price growth, YoY) | C12: MANUAL entry (slide 7) -- CPI PDF automation dropped by design; type the value from the NSO CPI presentation here
A13: Шатахууны үнийн өсөлт (Fuel price growth, YoY) | C13: MANUAL entry (slide 7) -- CPI PDF automation dropped by design; type the value from the NSO CPI presentation here
A16: Сарын цуваа (Monthly series, Mongolbank bulletin) — slides 6 & 8
A17: Сар (Month) | B17: Инфляц, улс (CPI YoY, national) | C17: Инфляц, УБ (CPI YoY, UB) | D17: Зорилт (Target) | E17: Бодлогын хүү (Policy rate) | F17: Хадгаламжийн хүү (Deposit rate, new MNT) | G17: Шинэ зээлийн хүү, зах зээлийн (New loan rate, market) | H17: Шинэ зээлийн хүү, хөтөлбөрийн зээл оруулснаар (incl. subsidised) | I17: Зөрүү (Gap, pp) | J17: Ам.долларын ханш (USD/MNT, eop)
A18: 2025-04 | B18: 0.087 | C18: 0.099 | D18: 0.08 | E18: 0.12 | F18: 0.1199 | G18: 0.172 | H18: 0.1662 | I18: =IFERROR((G18-H18)*100,"") | J18: 3570.82
A19: 2025-05 | B19: 0.083 | C19: 0.094 | D19: 0.08 | E19: 0.12 | F19: 0.1188 | G19: 0.1718 | H19: 0.1656 | I19: =IFERROR((G19-H19)*100,"") | J19: 3573.95
A20: 2025-06 | B20: 0.082 | C20: 0.094 | D20: 0.08 | E20: 0.12 | F20: 0.1159 | G20: 0.1727 | H20: 0.1681 | I20: =IFERROR((G20-H20)*100,"") | J20: 3580.94
A21: 2025-07 | B21: 0.081 | C21: 0.093 | D21: 0.08 | E21: 0.12 | F21: 0.114 | G21: 0.171 | H21: 0.1687 | I21: =IFERROR((G21-H21)*100,"") | J21: 3587.49
A22: 2025-08 | B22: 0.088 | C22: 0.098 | D22: 0.08 | E22: 0.12 | F22: 0.1172 | G22: 0.1703 | H22: 0.168 | I22: =IFERROR((G22-H22)*100,"") | J22: 3592.79
A23: 2025-09 | B23: 0.09 | C23: 0.099 | D23: 0.08 | E23: 0.12 | F23: 0.1187 | G23: 0.1726 | H23: 0.1692 | I23: =IFERROR((G23-H23)*100,"") | J23: 3592.78
A24: 2025-10 | B24: 0.092 | C24: 0.099 | D24: 0.08 | E24: 0.12 | F24: 0.1228 | G24: 0.1736 | H24: 0.1697 | I24: =IFERROR((G24-H24)*100,"") | J24: 3585.29
A25: 2025-11 | B25: 0.082 | C25: 0.087 | D25: 0.08 | E25: 0.12 | F25: 0.117 | G25: 0.1734 | H25: 0.1697 | I25: =IFERROR((G25-H25)*100,"") | J25: 3553.58
A26: 2025-12 | B26: 0.075 | C26: 0.076 | D26: 0.08 | E26: 0.12 | F26: 0.1203 | G26: 0.1727 | H26: 0.1674 | I26: =IFERROR((G26-H26)*100,"") | J26: 3556.81
A27: 2026-01 | B27: 0.075 | C27: 0.075 | D27: 0.08 | E27: 0.12 | F27: 0.1174 | G27: 0.1713 | H27: 0.1698 | I27: =IFERROR((G27-H27)*100,"") | J27: 3564.08
A28: 2026-02 | B28: 0.065 | C28: 0.06 | D28: 0.08 | E28: 0.12 | F28: 0.1184 | G28: 0.1726 | H28: 0.1709 | I28: =IFERROR((G28-H28)*100,"") | J28: 3565.55
A29: 2026-03 | B29: 0.074 | C29: 0.073 | D29: 0.08 | E29: 0.12 | F29: 0.1184 | G29: 0.1759 | H29: 0.1737 | I29: =IFERROR((G29-H29)*100,"") | J29: 3568.71
... A33: 2026-07 | B33: 0.13 | C33: 0.13 | D33: 0.08 | E33: 0.12 | F33: 0.1144 | G33: 0.1741 | H33: 0.1723 | I33: =IFERROR((G33-H33)*100,"") | J33: 3592.73
A36: Инфляцад нөлөөлж буй бүлгүүд (CPI component contributions to headline, 2026-07)
A37: Бүлэг (Category) | B37: Хувь нэмэр, 2026-07 (pp) | C37: Эзлэх хувь, 2026-07 (share) | D37: Хувь нэмэр, 2025-07 (pp) | E37: Эзлэх хувь, 2025-07 (share) | F37: Бүлгийн өсөлт (Category YoY) | G37: Индекс (Level)
A38: Хүнсний бараа, согтууруулах бус ундаа Food & non-alcoholic beverages | B38: 7.01 | C38: 0.53716475 | D38: 1.8 | E38: 0.22222222 | F38: 0.255 | G38: 39.46
A39: Тээвэр Transports | B39: 1.48 | C39: 0.11340996 | D39: 0.44 | E39: 0.054320988 | F39: 0.1 | G39: 18.63
A40: Хувцас, бөс бараа, гутал Clothing, footwear and cloths | B40: 0.93 | C40: 0.071264368 | D40: 1.17 | E40: 0.14444444 | F40: 0.072 | G40: 15.86
A41: Боловсролын үйлчилгээ Education | B41: 0.76 | C41: 0.058237548 | D41: 1 | E41: 0.12345679 | F41: 0.128 | G41: 7.72
A42: Бусад бараа үйлчилгээ Miscellaneous goods & services | B42: 0.58 | C42: 0.044444444 | D42: 0.59 | E42: 0.072839506 | F42: 0.098 | G42: 7.51
A43: Орон сууц, ус, түлш, цахилгаан Housing, water, electricity, and fuels | B43: 0.54 | C43: 0.04137931 | D43: 1.89 | E43: 0.23333333 | F43: 0.051 | G43: 12.7
A44: Эм, тариа, эмнэлгийн үйлчилгээ Medical care & services | B44: 0.53 | C44: 0.040613027 | D44: 0.38 | E44: 0.04691358 | F44: 0.076 | G44: 8.6
A45: Зочид буудал, нийтийн хоол, дотуур байр Restraurants hotels | B45: 0.43 | C45: 0.032950192 | D45: 0.3 | E45: 0.037037037 | F45: 0.162 | G45: 3.49
A46: Гэр ахуйн тавилга, гэр ахуйн бараа Furnishings, household equipment & tools | B46: 0.41 | C46: 0.031417625 | D46: 0.3 | E46: 0.037037037 | F46: 0.087 | G46: 5.87
A47: Согтууруу- лах ундаа, тамхи Alcoholic beverages, tobacco | B47: 0.12 | C47: 0.0091954023 | D47: 0.04 | E47: 0.0049382716 | F47: 0.126 | G47: 1.23
A48: Амралт, чөлөөт цаг, соёлын бараа үйлчилгээ Recreation & culture | B48: 0.1 | C48: 0.0076628352 | D48: 0.09 | E48: 0.011111111 | F48: 0.066 | G48: 1.82
A49: Холбооны хэрэгсэл, шуудангийн үйлчилгээ Communi- cation | B49: 0.08 | C49: 0.0061302682 | D49: 0.04 | E49: 0.0049382716 | F49: 0.016 | G49: 6.03
...

Sheet Trade
A1: Foreign trade
A2: Deck slide 9. Source: Customs gaali.mn monthly bulletin, sheet 1. Money: thousand USD unless noted. YoY/balance columns are formulas.
A4: МЭДЭЭЛЛИЙН ОН САР / DATA AS OF: Customs (gaali.mn) — 2026-07 (CURRENT) [тайлант үе / reported month: 2026-07]
A6: Үзүүлэлт (Indicator) | B6: Өмнөх он (Prev year, cum.) | C6: Тайлант он (Current year, cum.) | D6: Өсөлт (YoY) | E6: сая $ (mln USD, cur.)
A7: Экспорт (Export) | B7: 7751535.2 | C7: 12205932 | D7: =IFERROR(C7/B7-1,"") | E7: =IFERROR(C7/1000,"")
A8: Импорт (Import) | B8: 6480784.2 | C8: 7158063.4 | D8: =IFERROR(C8/B8-1,"") | E8: =IFERROR(C8/1000,"")
A9: Худалдааны тэнцэл (Trade balance) | B9: =B7-B8 | C9: =C7-C8 | D9: =IFERROR(C9/B9,"") | E9: =IFERROR(C9/1000,"")
A12: Сар бүрийн өссөн худалдаа (Monthly cumulative trade, mln USD) — grows as monthly workbooks are cached
A13: Он (Year) | B13: Сар (Month) | C13: Экспорт, өссөн (Export cum., mln $) | D13: Импорт, өссөн (Import cum., mln $) | E13: Тэнцэл (Balance, mln $) | F13: Экспортын өсөлт (Export YoY) | G13: Импортын өсөлт (Import YoY) | H13: Нийт эргэлт (Turnover, mln $) | I13: Эргэлтийн өсөлт (Turnover YoY)
A14: 2024 | B14: 1 | C14: 1324.925 | D14: 935.9896 | E14: =C14-D14 | H14: =C14+D14
A15: 2024 | B15: 2 | C15: 2240.2788 | D15: 1595.8787 | E15: =C15-D15 | H15: =C15+D15
A16: 2024 | B16: 3 | C16: 3658.8553 | D16: 2414.2793 | E16: =C16-D16 | H16: =C16+D16
A17: 2024 | B17: 4 | C17: 4937.0968 | D17: 3426.2195 | E17: =C17-D17 | H17: =C17+D17
A18: 2024 | B18: 5 | C18: 6355.9796 | D18: 4395.1571 | E18: =C18-D18 | H18: =C18+D18
A19: 2024 | B19: 6 | C19: 7886.2146 | D19: 5378.4283 | E19: =C19-D19 | H19: =C19+D19
A20: 2024 | B20: 7 | C20: 9265.8501 | D20: 6411.1281 | E20: =C20-D20 | H20: =C20+D20
A21: 2024 | B21: 8 | C21: 10625.089 | D21: 7501.6131 | E21: =C21-D21 | H21: =C21+D21
A22: 2024 | B22: 9 | C22: 11782.653 | D22: 8608.2879 | E22: =C22-D22 | H22: =C22+D22
A23: 2024 | B23: 10 | C23: 13207.173 | D23: 9579.7805 | E23: =C23-D23 | H23: =C23+D23
A24: 2024 | B24: 11 | C24: 14596.419 | D24: 10567.099 | E24: =C24-D24 | H24: =C24+D24
A25: 2025 | B25: 1 | C25: 1019.1869 | D25: 973.1577 | E25: =C25-D25 | F25: =IFERROR(C25/C14-1,"") | G25: =IFERROR(D25/D14-1,"") | H25: =C25+D25 | I25: =IFERROR(H25/H14-1,"")
A26: 2025 | B26: 2 | C26: 2004.9174 | D26: 1710.8877 | E26: =C26-D26 | F26: =IFERROR(C26/C15-1,"") | G26: =IFERROR(D26/D15-1,"") | H26: =C26+D26 | I26: =IFERROR(H26/H15-1,"")
A27: 2025 | B27: 3 | C27: 3013.0441 | D27: 2547.9754 | E27: =C27-D27 | F27: =IFERROR(C27/C16-1,"") | G27: =IFERROR(D27/D16-1,"") | H27: =C27+D27 | I27: =IFERROR(H27/H16-1,"")
A28: 2025 | B28: 4 | C28: 4242.5935 | D28: 3559.4164 | E28: =C28-D28 | F28: =IFERROR(C28/C17-1,"") | G28: =IFERROR(D28/D17-1,"") | H28: =C28+D28 | I28: =IFERROR(H28/H17-1,"")
A29: 2025 | B29: 5 | C29: 5424.5923 | D29: 4540.0817 | E29: =C29-D29 | F29: =IFERROR(C29/C18-1,"") | G29: =IFERROR(D29/D18-1,"") | H29: =C29+D29 | I29: =IFERROR(H29/H18-1,"")
A30: 2025 | B30: 6 | C30: 6581.3934 | D30: 5528.2273 | E30: =C30-D30 | F30: =IFERROR(C30/C19-1,"") | G30: =IFERROR(D30/D19-1,"") | H30: =C30+D30 | I30: =IFERROR(H30/H19-1,"")
A31: 2025 | B31: 7 | C31: 7751.5352 | D31: 6480.7842 | E31: =C31-D31 | F31: =IFERROR(C31/C20-1,"") | G31: =IFERROR(D31/D20-1,"") | H31: =C31+D31 | I31: =IFERROR(H31/H20-1,"")
A32: 2025 | B32: 8 | C32: 9158.1271 | D32: 7476.6528 | E32: =C32-D32 | F32: =IFERROR(C32/C21-1,"") | G32: =IFERROR(D32/D21-1,"") | H32: =C32+D32 | I32: =IFERROR(H32/H21-1,"")
A33: 2025 | B33: 9 | C33: 10708.601 | D33: 8533.8394 | E33: =C33-D33 | F33: =IFERROR(C33/C22-1,"") | G33: =IFERROR(D33/D22-1,"") | H33: =C33+D33 | I33: =IFERROR(H33/H22-1,"")
A34: 2025 | B34: 10 | C34: 12230.59 | D34: 9365.7159 | E34: =C34-D34 | F34: =IFERROR(C34/C23-1,"") | G34: =IFERROR(D34/D23-1,"") | H34: =C34+D34 | I34: =IFERROR(H34/H23-1,"")
A35: 2025 | B35: 11 | C35: 13742.486 | D35: 10210.61 | E35: =C35-D35 | F35: =IFERROR(C35/C24-1,"") | G35: =IFERROR(D35/D24-1,"") | H35: =C35+D35 | I35: =IFERROR(H35/H24-1,"")
A36: 2026 | B36: 1 | C36: 1749.4153 | D36: 842.9573 | E36: =C36-D36 | F36: =IFERROR(C36/C25-1,"") | G36: =IFERROR(D36/D25-1,"") | H36: =C36+D36 | I36: =IFERROR(H36/H25-1,"")
... A42: 2026 | B42: 7 | C42: 12205.932 | D42: 7158.0634 | E42: =C42-D42 | F42: =IFERROR(C42/C31-1,"") | G42: =IFERROR(D42/D31-1,"") | H42: =C42+D42 | I42: =IFERROR(H42/H31-1,"")

Sheet Commodities
A1: Commodity exports & imports
A2: Deck slides 9-10. Source: Customs sheet 8 / 8.2 / 3, matched by HS code. Quantities in kg; amounts in thousand USD; every derived column is a formula.
A4: МЭДЭЭЛЛИЙН ОН САР / DATA AS OF: Customs (gaali.mn) — 2026-07 (CURRENT) [тайлант үе / reported month: 2026-07]
A6: Экспортын бараа (Export commodity) | B6: HS | C6: Тоо, өмнөх (Qty prev, kg) | D6: Тоо, тайлант (Qty cur, kg) | E6: Тооны өсөлт (Qty YoY) | F6: Дүн, өмнөх (Amt prev, k$) | G6: Дүн, тайлант (Amt cur, k$) | H6: Дүнгийн өсөлт (Amt YoY) | I6: сая $ (mln $) | J6: Хэмжээ (Volume, deck unit) | K6: Нэгж (Unit)
A7: Чулуун нүүрс (Coal) | B7: 2701 | C7: 41347829700 | D7: 65575819700 | E7: =IFERROR(D7/C7-1,"") | F7: 2916910.7 | G7: 4636834 | H7: =IFERROR(G7/F7-1,"") | I7: =IFERROR(G7/1000,"") | J7: =IFERROR(D7/1E9,"") | K7: mln t
A8: Зэсийн хүдэр, баяжмал (Copper concentrate) | B8: 2603 | C8: 1242814810 | D8: 1528828900 | E8: =IFERROR(D8/C8-1,"") | F8: 2879141.6 | G8: 5460531.9 | H8: =IFERROR(G8/F8-1,"") | I8: =IFERROR(G8/1000,"") | J8: =IFERROR(D8/1E6,"") | K8: thous. t
A9: Мөнгөжөөгүй алт (Gold, unwrought) | B9: 7108 | C9: 4727.9 | D9: 3060.8 | E9: =IFERROR(D9/C9-1,"") | F9: 472467.5 | G9: 482132.9 | H9: =IFERROR(G9/F9-1,"") | I9: =IFERROR(G9/1000,"") | J9: =D9 | K9: kg
A10: Төмрийн хүдэр, баяжмал (Iron ore & concentrate) | B10: 2601 | C10: 4681300519 | D10: 5162259101 | E10: =IFERROR(D10/C10-1,"") | F10: 332442 | G10: 364686.5 | H10: =IFERROR(G10/F10-1,"") | I10: =IFERROR(G10/1000,"") | J10: =IFERROR(D10/1E9,"") | K10: mln t
A11: Ноос, ноолуур (Wool & cashmere) | B11: ch51 | C11: 4461.753 | D11: 6890.7871 | E11: =IFERROR(D11/C11-1,"") | F11: 90444.824 | G11: 169775.38 | H11: =IFERROR(G11/F11-1,"") | I11: =IFERROR(G11/1000,"")
A14: Импортын бараа (Import commodities)
A15: Импортын бараа (Import commodity) | B15: HS/section | C15: Дүн, өмнөх (Amt prev, k$) | D15: Дүн, тайлант (Amt cur, k$) | E15: Дүнгийн өсөлт (Amt YoY) | F15: сая $ (mln $)
A16: Нефтийн бүтээгдэхүүн (Petroleum products) | B16: 2710 | C16: 1153491.9 | D16: 1557290 | E16: =IFERROR(D16/C16-1,"") | F16: =IFERROR(D16/1000,"")
A17: Суудлын автомашин (Passenger cars) | B17: 8703 | C17: 762229.1 | D17: 607433.2 | E17: =IFERROR(D17/C17-1,"") | F17: =IFERROR(D17/1000,"")
A18: Цахилгаан эрчим хүч (Electricity) | B18: 2716 | C18: 121600.8 | D18: 142564.8 | E18: =IFERROR(D18/C18-1,"") | F18: =IFERROR(D18/1000,"")
A19: Ачааны автомашин (Trucks) | B19: 8704 | C19: 326193.9 | D19: 269325.1 | E19: =IFERROR(D19/C19-1,"") | F19: =IFERROR(D19/1000,"")
A20: Машин, тоног төхөөрөмж (Machinery & equipment) | B20: sec16 | C20: 1346721.7 | D20: 1464975.4 | E20: =IFERROR(D20/C20-1,"") | F20: =IFERROR(D20/1000,"")
A21: Үндсэн төмөрлөг (Base metals) | B21: sec15 | C21: 590032.73 | D21: 662621.03 | E21: =IFERROR(D21/C21-1,"") | F21: =IFERROR(D21/1000,"")
A22: Хүнсний бүтээгдэхүүн (Food products) | B22: sec04 | C22: 497805.8 | D22: 531988.41 | E22: =IFERROR(D22/C22-1,"") | F22: =IFERROR(D22/1000,"")

Sheet Trade_Sections
A1: Худалдаа, хэсгээр (Trade by HS section)
A2: Full sectional detail behind slide 9. Source: Customs sheet 3, thousand USD, cumulative both years. Export and import are separate tables, each ranked by its own current-year value; YoY, share and totals are formulas.
A4: МЭДЭЭЛЛИЙН ОН САР / DATA AS OF: Customs (gaali.mn) — 2026-07 (CURRENT) [тайлант үе / reported month: 2026-07]
A6: ЭКСПОРТ, хэсгээр (EXPORT by HS section)
A7: Ranked by current-year export value. Total must equal the headline export figure on the Trade sheet.
A8: Эрэмбэ (Rank) | B8: Хэсэг (HS section) | C8: Өмнөх он (Previous, k$) | D8: Тайлант он (Current, k$) | E8: Өсөлт (YoY) | F8: Хувь (Share)
A9: 1 | B9: 05 Эрдэс бүтээгдэхүүн (Mineral products) | C9: 6848988.4 | D9: 11246857 | E9: =IFERROR(D9/C9-1,"") | F9: =IFERROR(D9/D$30,"")
A10: 2 | B10: 14 Сувд, үнэт ба хагас үнэт чулуу, үнэт металл, гоёлын зүйлс, зоос (Natural or cultured pearls, precious or semi-precious stones) | C10: 478696.28 | D10: 488697.6 | E10: =IFERROR(D10/C10-1,"") | F10: =IFERROR(D10/D$30,"")
A11: 3 | B11: 11 Нэхмэлийн материал болон нэхмэл эдлэл (Textiles and textile articles) | C11: 102222.57 | D11: 180781.5 | E11: =IFERROR(D11/C11-1,"") | F11: =IFERROR(D11/D$30,"")
A12: 4 | B12: 15 Үндсэн төмөрлөг болон түүгээр хийсэн бүтээгдэхүүн (Base metals and articles thereof) | C12: 103628 | D12: 82424.924 | E12: =IFERROR(D12/C12-1,"") | F12: =IFERROR(D12/D$30,"")
A13: 5 | B13: 16 Машин, механик тоног төхөөрөмж ба эд анги, цахилгаан хэрэгсэл, тэдг (Machinery and mechanical appliances; electrical equipments, ) | C13: 35201.891 | D13: 57189.476 | E13: =IFERROR(D13/C13-1,"") | F13: =IFERROR(D13/D$30,"")
A14: 6 | B14: 01 Амьд мал, амьтад, мал амьтдын гаралтай бүтээгдэхүүн (Live animals, animal products) | C14: 55073.601 | D14: 46187.249 | E14: =IFERROR(D14/C14-1,"") | F14: =IFERROR(D14/D$30,"")
A15: 7 | B15: 04 Хүнсний бэлэн бүтээгдэхүүн (Prepared foodstuffs) | C15: 33974.85 | D15: 44206.419 | E15: =IFERROR(D15/C15-1,"") | F15: =IFERROR(D15/D$30,"")
A16: 8 | B16: 17 Авто, агаарын ба усан замын тээврийн хэрэгсэл, тэдгээрийн эд, анги (Vehicles, aircraft, vessets and parts thereof) | C16: 15818.454 | D16: 31953.276 | E16: =IFERROR(D16/C16-1,"") | F16: =IFERROR(D16/D$30,"")
A17: 9 | B17: 02 Ургамлын гаралтай бүтээгдэхүүн (Vegetable products) | C17: 63966.442 | D17: 10468.763 | E17: =IFERROR(D17/C17-1,"") | F17: =IFERROR(D17/D$30,"")
A18: 10 | B18: 03 Мал амьтны болон ургамлын гаралтай тос, өөх (Animal or vegetable fats oils) | C18: 2301.5336 | D18: 5170.8783 | E18: =IFERROR(D18/C18-1,"") | F18: =IFERROR(D18/D$30,"")
A19: 11 | B19: 07 Хуванцар болон түүгээр хийсэн зүйлс; хаймар болон түүгээр хийсэн зү (Plastics and rubber and articles thereof) | C19: 6363.1684 | D19: 3416.1822 | E19: =IFERROR(D19/C19-1,"") | F19: =IFERROR(D19/D$30,"")
A20: 12 | B20: 18 Хараа зүй, гэрэл зураг, хэмжүүр, хяналт, эмнэлгийн багаж хэрэгсэл, (Optical, photographic, measuring, checking, medical instrume) | C20: 1737.6561 | D20: 2928.3412 | E20: =IFERROR(D20/C20-1,"") | F20: =IFERROR(D20/D$30,"")
... A28: 20 | B28: 10 Цаас болон картон, тэдгээрээр хийсэн зүйлс (Pulp of wood) | C28: 17.729025 | D28: 11.552394 | E28: =IFERROR(D28/C28-1,"") | F28: =IFERROR(D28/D$30,"")
A29: 21 | B29: Бусад (Other) | C29: 0 | D29: 0
B30: Нийт (Total) | C30: =SUM(C9:C29) | D30: =SUM(D9:D29) | E30: =IFERROR(D30/C30-1,"") | F30: =SUM(F9:F29)
A32: ИМПОРТ, хэсгээр (IMPORT by HS section)
A33: Ranked independently by current-year import value -- the order differs from the export table by design.
A34: Эрэмбэ (Rank) | B34: Хэсэг (HS section) | C34: Өмнөх он (Previous, k$) | D34: Тайлант он (Current, k$) | E34: Өсөлт (YoY) | F34: Хувь (Share)
A35: 1 | B35: 05 Эрдэс бүтээгдэхүүн (Mineral products) | C35: 1322392.9 | D35: 1795032.7 | E35: =IFERROR(D35/C35-1,"") | F35: =IFERROR(D35/D$56,"")
A36: 2 | B36: 16 Машин, механик тоног төхөөрөмж ба эд анги, цахилгаан хэрэгсэл, тэдг (Machinery and mechanical appliances; electrical equipments, ) | C36: 1346721.7 | D36: 1464975.4 | E36: =IFERROR(D36/C36-1,"") | F36: =IFERROR(D36/D$56,"")
A37: 3 | B37: 17 Авто, агаарын ба усан замын тээврийн хэрэгсэл, тэдгээрийн эд, анги (Vehicles, aircraft, vessets and parts thereof) | C37: 1383507.1 | D37: 1137721.4 | E37: =IFERROR(D37/C37-1,"") | F37: =IFERROR(D37/D$56,"")
A38: 4 | B38: 15 Үндсэн төмөрлөг болон түүгээр хийсэн бүтээгдэхүүн (Base metals and articles thereof) | C38: 590032.73 | D38: 662621.03 | E38: =IFERROR(D38/C38-1,"") | F38: =IFERROR(D38/D$56,"")
A39: 5 | B39: 04 Хүнсний бэлэн бүтээгдэхүүн (Prepared foodstuffs) | C39: 497805.8 | D39: 531988.41 | E39: =IFERROR(D39/C39-1,"") | F39: =IFERROR(D39/D$56,"")
A40: 6 | B40: 06 Химийн болон түүнтэй холбоотой үйлдвэрийн бүтээгдэхүүн (Products of the chemical or allied industries) | C40: 373473.61 | D40: 412892.77 | E40: =IFERROR(D40/C40-1,"") | F40: =IFERROR(D40/D$56,"")
A41: 7 | B41: 07 Хуванцар болон түүгээр хийсэн зүйлс; хаймар болон түүгээр хийсэн зү (Plastics and rubber and articles thereof) | C41: 218553.61 | D41: 299082.47 | E41: =IFERROR(D41/C41-1,"") | F41: =IFERROR(D41/D$56,"")
A42: 8 | B42: 13 Чулуу, гөлтгөнө, шөрмөсөн чулуу, гялтгануур болон тэдгээртэй төстэй (Articles of stone, flaster, cement, asbestos, mica or simira) | C42: 143887.18 | D42: 155066.76 | E42: =IFERROR(D42/C42-1,"") | F42: =IFERROR(D42/D$56,"")
A43: 9 | B43: 02 Ургамлын гаралтай бүтээгдэхүүн (Vegetable products) | C43: 105041.45 | D43: 146577.45 | E43: =IFERROR(D43/C43-1,"") | F43: =IFERROR(D43/D$56,"")
A44: 10 | B44: 18 Хараа зүй, гэрэл зураг, хэмжүүр, хяналт, эмнэлгийн багаж хэрэгсэл, (Optical, photographic, measuring, checking, medical instrume) | C44: 92475.566 | D44: 97453.025 | E44: =IFERROR(D44/C44-1,"") | F44: =IFERROR(D44/D$56,"")
A45: 11 | B45: 20 Аж үйлдвэрийн төрөл бүрийн бараа (Miscellaneous manufactured articles) | C45: 82908.749 | D45: 95924.827 | E45: =IFERROR(D45/C45-1,"") | F45: =IFERROR(D45/D$56,"")
A46: 12 | B46: 01 Амьд мал, амьтад, мал амьтдын гаралтай бүтээгдэхүүн (Live animals, animal products) | C46: 81569.355 | D46: 95350.447 | E46: =IFERROR(D46/C46-1,"") | F46: =IFERROR(D46/D$56,"")
... A55: 21 | B55: 21 Урлагийн бүтээл, цуглуулга хийх, зориулалтын зүйлс ба эртний үнэт д (Works of art, collectors pieces and antiques) | C55: 147.15224 | D55: 259.63553 | E55: =IFERROR(D55/C55-1,"") | F55: =IFERROR(D55/D$56,"")
B56: Нийт (Total) | C56: =SUM(C35:C55) | D56: =SUM(D35:D55) | E56: =IFERROR(D56/C56-1,"") | F56: =SUM(F35:F55)

Sheet Border_Prices
A1: Border prices (export unit values)
A2: Deck slide 11. Unit value = Δcumulative amount / Δcumulative quantity per month, from Customs sheet 8. Series fills in as monthly workbooks are cached by the ingestor.
A4: МЭДЭЭЛЛИЙН ОН САР / DATA AS OF: Customs (gaali.mn) — 2026-07 (CURRENT) [тайлант үе / reported month: 2026-07]
A6: Бараа (Commodity) | B6: Он (Year) | C6: Сар (Month) | D6: Үнэ (Price) | E6: Нэгж (Unit) | F6: Өсөлт (YoY) | G6: Basis
A7: Нүүрс (Coal) | B7: 2024 | C7: 1 | D7: 121.8 | E7: USD/t | G7: monthly
A8: Нүүрс (Coal) | B8: 2024 | C8: 2 | D8: 132.6 | E8: USD/t | G8: monthly
A9: Нүүрс (Coal) | B9: 2024 | C9: 3 | D9: 124.5 | E9: USD/t | G9: monthly
A10: Нүүрс (Coal) | B10: 2024 | C10: 4 | D10: 114.4 | E10: USD/t | G10: monthly
A11: Нүүрс (Coal) | B11: 2024 | C11: 5 | D11: 114.6 | E11: USD/t | G11: monthly
A12: Нүүрс (Coal) | B12: 2024 | C12: 6 | D12: 110.3 | E12: USD/t | G12: monthly
A13: Нүүрс (Coal) | B13: 2024 | C13: 7 | D13: 103.1 | E13: USD/t | G13: monthly
A14: Нүүрс (Coal) | B14: 2024 | C14: 8 | D14: 100.5 | E14: USD/t | G14: monthly
A15: Нүүрс (Coal) | B15: 2024 | C15: 9 | D15: 97 | E15: USD/t | G15: monthly
A16: Нүүрс (Coal) | B16: 2024 | C16: 10 | D16: 96.9 | E16: USD/t | G16: monthly
A17: Нүүрс (Coal) | B17: 2024 | C17: 11 | D17: 91.7 | E17: USD/t | G17: monthly
A18: Нүүрс (Coal) | B18: 2025 | C18: 1 | D18: 86.2 | E18: USD/t | F18: =IFERROR(D18/D7-1,"") | G18: monthly
A19: Нүүрс (Coal) | B19: 2025 | C19: 2 | D19: 81.3 | E19: USD/t | F19: =IFERROR(D19/D8-1,"") | G19: monthly
A20: Нүүрс (Coal) | B20: 2025 | C20: 3 | D20: 75.7 | E20: USD/t | F20: =IFERROR(D20/D9-1,"") | G20: monthly
A21: Нүүрс (Coal) | B21: 2025 | C21: 4 | D21: 68.8 | E21: USD/t | F21: =IFERROR(D21/D10-1,"") | G21: monthly
A22: Нүүрс (Coal) | B22: 2025 | C22: 5 | D22: 67 | E22: USD/t | F22: =IFERROR(D22/D11-1,"") | G22: monthly
A23: Нүүрс (Coal) | B23: 2025 | C23: 6 | D23: 62.5 | E23: USD/t | F23: =IFERROR(D23/D12-1,"") | G23: monthly
A24: Нүүрс (Coal) | B24: 2025 | C24: 7 | D24: 57.4 | E24: USD/t | F24: =IFERROR(D24/D13-1,"") | G24: monthly
A25: Нүүрс (Coal) | B25: 2025 | C25: 8 | D25: 56.8 | E25: USD/t | F25: =IFERROR(D25/D14-1,"") | G25: monthly
A26: Нүүрс (Coal) | B26: 2025 | C26: 9 | D26: 61.4 | E26: USD/t | F26: =IFERROR(D26/D15-1,"") | G26: monthly
A27: Нүүрс (Coal) | B27: 2025 | C27: 10 | D27: 61.6 | E27: USD/t | F27: =IFERROR(D27/D16-1,"") | G27: monthly
A28: Нүүрс (Coal) | B28: 2025 | C28: 11 | D28: 63.9 | E28: USD/t | F28: =IFERROR(D28/D17-1,"") | G28: monthly
A29: Нүүрс (Coal) | B29: 2026 | C29: 1 | D29: 64.5 | E29: USD/t | F29: =IFERROR(D29/D18-1,"") | G29: monthly
... A35: Нүүрс (Coal) | B35: 2026 | C35: 7 | D35: 79.5 | E35: USD/t | F35: =IFERROR(D35/D24-1,"") | G35: monthly
A36: Зэсийн баяжмал (Copper concentrate) | B36: 2024 | C36: 1 | D36: 1773.9 | E36: USD/t | G36: monthly
A37: Зэсийн баяжмал (Copper concentrate) | B37: 2024 | C37: 2 | D37: 1737.3 | E37: USD/t | G37: monthly
A38: Зэсийн баяжмал (Copper concentrate) | B38: 2024 | C38: 3 | D38: 1695.4 | E38: USD/t | G38: monthly
A39: Зэсийн баяжмал (Copper concentrate) | B39: 2024 | C39: 4 | D39: 1769.7 | E39: USD/t | G39: monthly
A40: Зэсийн баяжмал (Copper concentrate) | B40: 2024 | C40: 5 | D40: 1943.1 | E40: USD/t | G40: monthly
A41: Зэсийн баяжмал (Copper concentrate) | B41: 2024 | C41: 6 | D41: 2136.5 | E41: USD/t | G41: monthly
A42: Зэсийн баяжмал (Copper concentrate) | B42: 2024 | C42: 7 | D42: 2053.5 | E42: USD/t | G42: monthly
A43: Зэсийн баяжмал (Copper concentrate) | B43: 2024 | C43: 8 | D43: 2007.5 | E43: USD/t | G43: monthly
A44: Зэсийн баяжмал (Copper concentrate) | B44: 2024 | C44: 9 | D44: 1994.3 | E44: USD/t | G44: monthly
A45: Зэсийн баяжмал (Copper concentrate) | B45: 2024 | C45: 10 | D45: 2052.4 | E45: USD/t | G45: monthly
A46: Зэсийн баяжмал (Copper concentrate) | B46: 2024 | C46: 11 | D46: 2052.2 | E46: USD/t | G46: monthly
A47: Зэсийн баяжмал (Copper concentrate) | B47: 2025 | C47: 1 | D47: 1950 | E47: USD/t | F47: =IFERROR(D47/D36-1,"") | G47: monthly
...

Sheet External_Sector
A1: Mongolbank statistics cards
A2: Deck slide 12 (BoP, reserves, external debt, FDI) and slide 16 inputs where exposed. Every card returned by the section sweep is listed.
A4: МЭДЭЭЛЛИЙН ОН САР / DATA AS OF: Mongolbank cards — see card dates (PER-CARD) | Balance of payments — 2026-06 (LAGGED) [тайлант үе / reported month: 2026-07] ← ЭНЭ ХУУДСЫН ТОО ӨМНӨХ САРЫНХ (previous month's data)
A6: Карт (Card) | B6: Утга (Reported value, raw text) | C6: Тоон утга (Parsed value) | D6: Огноо (As of) | E6: Section file
A7: Төлбөрийн тэнцэл | B7: 567 сая $, жилийн өөрчлөлт 1,017 сая $ | C7: 567 | D7: 2026 оны 6-р сар | E7: mongolbank_external.json
A8: Гадаад хөрөнгө оруулалтын позиц | B8: -45,914 сая $, жилийн өөрчлөлт 2% | C8: -45914 | D8: 2026 оны 1-р улирал | E8: mongolbank_external.json
A9: Монгол Улсын нийт гадаад өр | B9: 40,218 сая $, жилийн өөрчлөлт 6.2% | C9: 40218 | D9: 2026 оны 1-р улирал | E9: mongolbank_external.json
A10: Гадаад валютын улсын нөөц | B10: 7,963 сая $, жилийн өөрчлөлт 48% | C10: 7963 | D10: 2026 оны 7-р сар | E10: mongolbank_external.json
A11: Шууд хөрөнгө оруулалтын статистик | B11: 37,509 сая $, жилийн өөрчлөлт 11% | C11: 37509 | D11: 2026 оны 1-р улирал | E11: mongolbank_external.json
A12: Багцын хөрөнгө оруулалтын статистик | B12: Актив: 599 сая $, Пассив: -4,834 сая $, жилийн өөрчлөлт А:8%, П: 21% | C12: 599 | D12: 2026 оны 1-р улирал | E12: mongolbank_external.json
A13: Гадаад худалдаа | B13: Тэнцэл: 5,048 сая $, жилийн өөрчлөлт 3x | C13: 5048 | D13: 2026 оны 7-р сар | E13: mongolbank_external.json
A14: Мөнгөний үзүүлэлтүүд | B14: Нийт 53.1 их наяд ₮, жилийн өөрчлөлт +25.2% | C14: 53.1 | D14: 2026 оны 7-р сар | E14: mongolbank_section_10.json
A15: Банкны салбарын тайлан тэнцэл | B15: Нийт актив 88.3 их наяд төгрөг, жилийн өөрчлөлт +25.9% | C15: 88.3 | D15: 2026 оны 7-р сар | E15: mongolbank_section_10.json
A16: Хадгаламжийн байгууллагын тойм | B16: M2 мөнгөний өсөлтийн 15.8 нэгж хувийг ГЦА, 9.5 нэгж хувийг ДЦА бүрдүүлэв. | C16: 2 | D16: 2026 оны 7-р сар | E16: mongolbank_section_10.json
A17: Банкны салбарын зээл | B17: Нийт 47.9 их наяд ₮, жилийн өөрчлөлт +13.0% | C17: 47.9 | D17: 2026 оны 7-р сар | E17: mongolbank_section_10.json
A18: Хадгаламжийн байгууллагын зээл | B18: Нийт 48.2 их наяд төгрөг, жилийн өөрчлөлт +13.0% | C18: 48.2 | D18: 2026 оны 7-р сар | E18: mongolbank_section_10.json
... A21: Ногоон зээл | B21: Нийт 2.9 их наяд ₮, жилийн өөрчлөлт +46.2% | C21: 2.9 | D21: 2026 оны 1-р улирал | E21: mongolbank_section_10.json
A24: Balance of payments — annual sums (mln USD; latest year is YTD). Source: bop_manual.xlsx
A25: Данс (Account) | B25: 2025 | C25: 2026
A26: Урсгал данс (Current account) | B26: -2119.9 | C26: 207.2
A27: Хөрөнгийн данс (Capital account) | B27: 121.2 | C27: 50
A28: Санхүүгийн данс (Financial account) | B28: -3271.2 | C28: -209.3
A29: Алдаа болон орхигдуулга (Errors & omissions) | B29: -238.2 | C29: 100.1
A30: Төлбөрийн тэнцлийн нийт дүн (Overall balance) | B30: 1034.3 | C30: 566.6
A31: Нөөц хөрөнгө (Reserve assets) | B31: 1034.3 | C31: 566.6
A34: Төлбөрийн тэнцэл, бүлгээр (Balance of payments by section and component, mln USD)
A35: Each section is followed by its own components. Indented rows sit one level deeper and are already included in the line above them, so only the section rows should be added together.
A36: Бүлэг / бүрэлдэхүүн (Section / component) | B36: 2025 I-6 (mln USD) | C36: 2026 I-6 (mln USD) | D36: Өөрчлөлт (Change)
A37: I. УРСГАЛ ДАНС | B37: -1752.49 | C37: 207.21 | D37: =C37-B37
A38: Бараа ба үйлчилгээний худалдаа | B38: -686.65 | C38: 2765.8 | D38: =C38-B38
A39: 1. Бараа | B39: 720.68 | C39: 4513.47 | D39: =C39-B39
A40: 2. Үйлчилгээ | B40: -1407.32 | C40: -1747.68 | D40: =C40-B40
A41: 3. Анхдагч орлого | B41: -1213.19 | C41: -2700.41 | D41: =C41-B41
A42: 4. Хоёрдогч орлого | B42: 147.34 | C42: 141.83 | D42: =C42-B42
A43: II. ХӨРӨНГИЙН ДАНС | B43: 50.68 | C43: 49.95 | D43: =C43-B43
A44: 1. Үйлдвэрлэхгүй санхүүгийн бус хөрөнгийн өсөлт (Дт)/ бууралт (Кр) | B44: 0 | C44: 0 | D44: =C44-B44
A45: 2. Хөрөнгийн шилжүүлэг | B45: 50.68 | C45: 49.95 | D45: =C45-B45
A46: III. САНХҮҮГИЙН ДАНС | B46: -1257.23 | C46: -209.3 | D46: =C46-B46
A47: 1. Шууд хөрөнгө оруулалт | B47: -916.33 | C47: -1232.67 | D47: =C47-B47
A48: 2. Багцын хөрөнгө оруулалт | B48: -163.55 | C48: -155.54 | D48: =C48-B48
...

Sheet Banking
A1: Banking sector — consolidated bank balance sheet
A2: Deck slide 16. Source: Mongolbank 'Банкуудын нэгдсэн тайлан тэнцэл' xlsx (million MNT). change measured 2025.07.31 -> 2026.07.31 (earliest column in the report; not necessarily 31 Dec)
A4: МЭДЭЭЛЛИЙН ОН САР / DATA AS OF: Bank balance sheet — 2026-07 (CURRENT) | Deposit tree — 2026-07 (CURRENT) [тайлант үе / reported month: 2026-07]
A6: Үзүүлэлт (Indicator) | B6: Түвшин 2025.07.31 (Level, mln ₮) | C6: Түвшин 2026.07.31 (Level, mln ₮) | D6: Өөрчлөлт (Change since first col) | E6: их наяд ₮ (Latest, tln ₮)
A7: Нийт актив (Total assets) | B7: 70133414 | C7: 88314736 | D7: =IFERROR(C7/B7-1,"") | E7: =IFERROR(C7/1E6,"")
A8: Дотоодын нийт зээл (Total loans, domestic) | B8: 42795499 | C8: 48448814 | D8: =IFERROR(C8/B8-1,"") | E8: =IFERROR(C8/1E6,"")
A9: Төв банкны үнэт цаас (Central bank securities) | B9: 8124839.7 | C9: 13950234 | D9: =IFERROR(C9/B9-1,"") | E9: =IFERROR(C9/1E6,"")
A10: Харилцах, хадгаламж (Current accounts + deposits) | B10: 39711140 | C10: 49532868 | D10: =IFERROR(C10/B10-1,"") | E10: =IFERROR(C10/1E6,"")
A11: Анхаарал хандуулах зээл (Past-due / special mention) | B11: 1855928.4 | C11: 1236133.8 | D11: =IFERROR(C11/B11-1,"") | E11: =IFERROR(C11/1E6,"")
A12: Чанаргүй зээл (Non-performing loans) | B12: 1874067.3 | C12: 2242577.9 | D12: =IFERROR(C12/B12-1,"") | E12: =IFERROR(C12/1E6,"")
A13: Өөрийн хөрөнгө (Equity) | B13: 7709800.5 | C13: 8776028.9 | D13: =IFERROR(C13/B13-1,"") | E13: =IFERROR(C13/1E6,"")
A16: Сар бүрийн түвшин (Monthly levels, mln ₮) per balance-sheet metric
A17: Үзүүлэлт (Metric) | B17: 2025.07.31 | C17: 2025.12.31 | D17: 2026.06.30 | E17: 2026.07.31
A18: Нийт актив (Total assets) | B18: 70133414 | C18: 85425638 | D18: 92008677 | E18: 88314736
A19: Дотоодын нийт зээл (Total loans, domestic) | B19: 42795499 | C19: 44237247 | D19: 49478700 | E19: 48448814
A20: Төв банкны үнэт цаас (Central bank securities) | B20: 8124839.7 | C20: 10973337 | D20: 13939535 | E20: 13950234
A21: Харилцах, хадгаламж (Current accounts + deposits) | B21: 39711140 | C21: 42973445 | D21: 49437268 | E21: 49532868
A22: Анхаарал хандуулах зээл (Past-due / special mention) | B22: 1855928.4 | C22: 1492307.9 | D22: 1215900.1 | E22: 1236133.8
A23: Чанаргүй зээл (Non-performing loans) | B23: 1874067.3 | C23: 1949864.2 | D23: 2169931 | E23: 2242577.9
A24: Өөрийн хөрөнгө (Equity) | B24: 7709800.5 | C24: 8455129.5 | D24: 8641748.7 | E24: 8776028.9
A27: ХАРИЛЦАХ, ХАДГАЛАМЖ (deposits and current accounts, mln ₮) — Нийт пассив breakdown
A28: Each block splits by currency, then by tenor for savings, then by holder. Indented rows are already included in the line above them, so only the two top-level blocks add to total deposits. Source: deposits_export.json
A29: Үзүүлэлт (Item) | B29: 2025-01 | C29: 2025-02 | D29: 2025-03 | E29: 2025-04 | F29: 2025-05 | G29: 2025-06 | H29: 2025-07 | I29: 2025-08 | J29: 2025-09 | K29: 2025-10 | L29: 2025-11 | M29: 2025-12 | N29: 2026-01 | O29: 2026-02 | P29: 2026-03 | Q29: 2026-04 | R29: 2026-05 | S29: 2026-06 | T29: 2026-07 | U29: Өөрчлөлт (2026-06→2026-07) | V29: Эзлэх (Share)
A30: Аж ахуйн нэгж, иргэдийн харилцах | B30: 13150202 | C30: 12526979 | D30: 12182996 | E30: 12183805 | F30: 11862276 | G30: 12752707 | H30: 12285032 | I30: 13326207 | J30: 13130568 | K30: 13346462 | L30: 13425797 | M30: 13489327 | N30: 13507453 | O30: 14269744 | P30: 14780196 | Q30: 15942892 | R30: 16502834 | S30: 17979271 | T30: 17411336 | U30: =T30-S30 | V30: =IFERROR(T30/T$64,"")
A31: Төгрөгийн харилцах | B31: 9610957.4 | C31: 8941977.9 | D31: 8886313.7 | E31: 8628760.2 | F31: 8408479 | G31: 9305774.2 | H31: 8883870.2 | I31: 8929440.9 | J31: 9104660.2 | K31: 9544672.8 | L31: 9610032.9 | M31: 9643437.2 | N31: 9588710.6 | O31: 9214996.3 | P31: 9538602.1 | Q31: 10811126 | R31: 11090744 | S31: 11950516 | T31: 11007116 | U31: =T31-S31 | V31: =IFERROR(T31/T$64,"")
A32: Улсын байгууллага | B32: 2394583 | C32: 1458178.2 | D32: 1661321.8 | E32: 1255228.4 | F32: 1080688.8 | G32: 1038442.3 | H32: 994394.91 | I32: 1153962.8 | J32: 1014711.5 | K32: 1194217.5 | L32: 1573649 | M32: 1102172.4 | N32: 1640677.4 | O32: 1446935.2 | P32: 1323890.1 | Q32: 1989398.2 | R32: 1909453.1 | S32: 1934855.6 | T32: 1575441 | U32: =T32-S32 | V32: =IFERROR(T32/T$64,"")
A33: Хувийн байгууллага | B33: 3637348.1 | C33: 3706645 | D33: 3768232.1 | E33: 3543364 | F33: 3391993.4 | G33: 4062893.9 | H33: 3632904.5 | I33: 3732414 | J33: 3919103.4 | K33: 4173581.3 | L33: 4169000.6 | M33: 4447184.3 | N33: 4161537 | O33: 4085926.4 | P33: 4451591 | Q33: 4432960.6 | R33: 4702978.4 | S33: 5126683.3 | T33: 4673399 | U33: =T33-S33 | V33: =IFERROR(T33/T$64,"")
A34: Иргэд | B34: 3414214.4 | C34: 3616125.7 | D34: 3267647.6 | E34: 3632470.6 | F34: 3760464.6 | G34: 4017040.8 | H34: 4077990.3 | I34: 3844764.3 | J34: 3980571.7 | K34: 3991996.6 | L34: 3691658.9 | M34: 3914085.2 | N34: 3616843.5 | O34: 3490505.1 | P34: 3566286 | Q34: 4174335.9 | R34: 4253190.1 | S34: 4666194.8 | T34: 4552967 | U34: =T34-S34 | V34: =IFERROR(T34/T$64,"")
A35: Бусад байгууллага | B35: 164811.98 | C35: 161028.93 | D35: 189112.07 | E35: 197697.17 | F35: 175332.28 | G35: 187397.13 | H35: 178580.43 | I35: 198299.69 | J35: 190273.59 | K35: 184877.32 | L35: 175724.47 | M35: 179995.24 | N35: 169652.73 | O35: 191629.47 | P35: 196834.96 | Q35: 214430.82 | R35: 225122.45 | S35: 222782.72 | T35: 205308.9 | U35: =T35-S35 | V35: =IFERROR(T35/T$64,"")
A36: Гадаад валютын харилцах | B36: 3539245.1 | C36: 3585001.3 | D36: 3296682 | E36: 3555044.6 | F36: 3453797.4 | G36: 3446932.9 | H36: 3401162.3 | I36: 4396766.2 | J36: 4025908.1 | K36: 3801789.8 | L36: 3815764.4 | M36: 3845890.1 | N36: 3918742.7 | O36: 5054747.9 | P36: 5241593.5 | Q36: 5131766.8 | R36: 5412090.4 | S36: 6028754.6 | T36: 6404220 | U36: =T36-S36 | V36: =IFERROR(T36/T$64,"")
A37: Улсын байгууллага | B37: 488278.01 | C37: 701318.45 | D37: 468943.32 | E37: 517242.19 | F37: 366296.97 | G37: 357136.95 | H37: 389598.76 | I37: 413972.71 | J37: 547029.83 | K37: 443306.94 | L37: 536620.06 | M37: 593736.37 | N37: 645669.89 | O37: 1005684 | P37: 1583649.6 | Q37: 1335674.2 | R37: 1783152.1 | S37: 2282165.1 | T37: 2788586 | U37: =T37-S37 | V37: =IFERROR(T37/T$64,"")
A38: Хувийн байгууллага | B38: 2415739.6 | C38: 2321438.8 | D38: 2255461.3 | E38: 2409478 | F38: 2460393.8 | G38: 2477838.9 | H38: 2379010.8 | I38: 3362543.5 | J38: 2820946.8 | K38: 2743361.1 | L38: 2699642.5 | M38: 2692384.4 | N38: 2725192 | O38: 3498068.9 | P38: 3095521.7 | Q38: 3233269.6 | R38: 3066659.4 | S38: 3161963.9 | T38: 2992669 | U38: =T38-S38 | V38: =IFERROR(T38/T$64,"")
A39: Иргэд | B39: 580477.04 | C39: 506309.6 | D39: 515740.42 | E39: 552304.17 | F39: 558724.39 | G39: 546411.25 | H39: 567802.79 | I39: 555747.94 | J39: 576992.85 | K39: 546096.2 | L39: 511962.4 | M39: 502331.43 | N39: 487410.88 | O39: 488599.78 | P39: 489366.56 | Q39: 487091.72 | R39: 489233.06 | S39: 514731.04 | T39: 553111.4 | U39: =T39-S39 | V39: =IFERROR(T39/T$64,"")
A40: Бусад байгууллага | B40: 54750.45 | C40: 55934.43 | D40: 56536.95 | E40: 76020.32 | F40: 68382.21 | G40: 65545.85 | H40: 64749.98 | I40: 64502.01 | J40: 80938.62 | K40: 69025.56 | L40: 67539.46 | M40: 57437.92 | N40: 60470 | O40: 62395.24 | P40: 73055.64 | Q40: 75731.17 | R40: 73045.88 | S40: 69894.57 | T40: 69853.44 | U40: =T40-S40 | V40: =IFERROR(T40/T$64,"")
A41: Аж ахуйн нэгж, иргэдийн хадгаламж | B41: 25401797 | C41: 25923542 | D41: 26059834 | E41: 26134860 | F41: 26478853 | G41: 26916227 | H41: 27426108 | I41: 27423716 | J41: 27635390 | K41: 28308655 | L41: 28514308 | M41: 29484118 | N41: 29439824 | O41: 30087905 | P41: 30426832 | Q41: 30719195 | R41: 31330148 | S41: 31457997 | T41: 32121532 | U41: =T41-S41 | V41: =IFERROR(T41/T$64,"")
... A63: Бусад байгууллага | B63: 22144.21 | C63: 18759.42 | D63: 21973.18 | E63: 21502.12 | F63: 26636.89 | G63: 26348.28 | H63: 26362.2 | I63: 25533.05 | J63: 25395.08 | K63: 35200.45 | L63: 34756.06 | M63: 32689.96 | N63: 32967.29 | O63: 32238.1 | P63: 30407.71 | Q63: 30077.83 | R63: 27894 | S63: 26197.04 | T63: 27912.79 | U63: =T63-S63 | V63: =IFERROR(T63/T$64,"")
A64: Нийт харилцах, хадгаламж (Total deposits) | B64: =B30+B41 | C64: =C30+C41 | D64: =D30+D41 | E64: =E30+E41 | F64: =F30+F41 | G64: =G30+G41 | H64: =H30+H41 | I64: =I30+I41 | ... T64: =T30+T41

Sheet Loan_Detail
A1: Банкны салбарын зээл, дэлгэрэнгүй (Bank loans in detail)
A2: Mongolbank monthly loan report, 2026-07 (million MNT). The report is a flow statement, so the change in the loan book is decomposed rather than estimated. Growth, shares and totals are formulas.
A4: МЭДЭЭЛЛИЙН ОН САР / DATA AS OF: Bank loan report — 2026-07 (CURRENT) [тайлант үе / reported month: 2026-07]
A6: 0. ҮЗҮҮЛЭЛТҮҮД (indicators as published on stat.mongolbank.mn — Банкны салбарын зээл)
A7: Same figures as the portal's indicator list. Per the report's own Заавар sheet, 'хугацаа хэтэрсэн' is the special-mention class and 'чанаргүй' is substandard + doubtful + loss.
A8: Үзүүлэлт (Indicator) | B8: Нийт (Total) | C8: Үүнээс: төгрөгийн зээл (of which MNT) | D8: Валютын хувь (FX share) | E8: Нийт зээлд эзлэх (Share of book)
A9: Зээлийн үлдэгдэл (Loan balance) | B9: 47876124 | C9: 45062486 | D9: =IFERROR(1-C9/B9,"") | E9: =IFERROR(B9/B$9,"")
A10: Хугацаа хэтэрсэн зээлийн үлдэгдэл (Past due) | B10: 1236542.7 | C10: 1143146.3 | D10: =IFERROR(1-C10/B10,"") | E10: =IFERROR(B10/B$9,"")
A11: Чанаргүй зээлийн үлдэгдэл (Non-performing) | B11: 2510344.4 | C11: 2297151.8 | D11: =IFERROR(1-C11/B11,"") | E11: =IFERROR(B11/B$9,"")
A12: Төслөөр хэрэгжсэн зээлийн үлдэгдэл (Project loans) | B12: 3053100.4 | C12: 2968492.1 | D12: =IFERROR(1-C12/B12,"") | E12: =IFERROR(B12/B$9,"")
A14: 1. ЗЭЭЛИЙН ӨСӨЛТИЙН ЗАДАРГАА (how the loan book grew)
A15: Үзүүлэлт (Flow) | B15: Дүн (mln MNT)
A16: Эхний үлдэгдэл (Opening balance) | B16: 48957222
A17: + Олгосон зээл (Loans disbursed) | B17: 5840363.7
A18: − Төлөгдсөн зээл (Loans repaid) | B18: -6188131.5
A19: − Сангаас хаагдсан (Written off) | B19: 0
A20: ± Ханшийн тэгшитгэл (FX revaluation) | B20: 12789.25
A21: ± Бусад гүйлгээ (Other movements) | B21: -746119.35
A22: Эцсийн үлдэгдэл (Closing balance, computed) | B22: =SUM(B16:B21)
A23: Тайлант эцсийн үлдэгдэл (Closing, as reported) | B23: 47876124
A24: Зөрүү (Residual — must be 0) | B24: =B22-B23
A25: Өөрчлөлт (Net change) | B25: =B23-B16
A26: Өсөлт, сараар (Growth, month on month) | B26: =IFERROR(B23/B16-1,"")
A27: Өсөлт, жилээр (Growth YoY vs 2025-07) | B27: 0.1302
A29: 2. САЛБАРААР (by economic sector — what drove it)
A30: Ranked by contribution to the month's growth. The pp column sums to the total growth rate above.
A31: Код | B31: Салбар (Sector) | C31: Эхний үлдэгдэл (Opening) | D31: Эцсийн үлдэгдэл (Closing) | E31: Өөрчлөлт (Change) | F31: Хувь нэмэр (pp) | G31: Эзлэх (Share) | H31: Үүнээс: төгрөгийн (of which MNT) | I31: Жилийн өсөлт (YoY)
A32: H | B32: ТЭЭВЭР, АГУУЛАХЫН ҮЙЛ АЖИЛЛАГАА | C32: 1489751.3 | D32: 1556925.5 | E32: =D32-C32 | F32: =IFERROR((D32-C32)/C$54*100,"") | G32: =IFERROR(D32/D$54,"") | H32: 1026811.8 | I32: 0.35
A33: B | B33: УУЛ УУРХАЙ, ОЛБОРЛОЛТ | C33: 2684186.8 | D33: 2731598.2 | E33: =D33-C33 | F33: =IFERROR((D33-C33)/C$54*100,"") | G33: =IFERROR(D33/D$54,"") | H33: 1725309.5 | I33: 0.14
A34: P | B34: БОЛОВСРОЛ | C34: 485784.95 | D34: 499339.79 | E34: =D34-C34 | F34: =IFERROR((D34-C34)/C$54*100,"") | G34: =IFERROR(D34/D$54,"") | H34: 499305.85 | I34: 0.206
A35: I | B35: ЗОЧИД БУУДАЛ, БАЙР, СУУЦ БОЛОН НИЙТИЙН ХООЛНЫ ҮЙЛЧИЛГЭЭ | C35: 929616.11 | D35: 942750.19 | E35: =D35-C35 | F35: =IFERROR((D35-C35)/C$54*100,"") | G35: =IFERROR(D35/D$54,"") | H35: 912851.59 | I35: 0.512
A36: N | B36: УДИРДЛАГЫН БОЛОН ДЭМЖЛЭГ ҮЗҮҮЛЭХ ҮЙЛ АЖИЛЛАГАА | C36: 243510.57 | D36: 251717.28 | E36: =D36-C36 | F36: =IFERROR((D36-C36)/C$54*100,"") | G36: =IFERROR(D36/D$54,"") | H36: 235904.78 | I36: 0.822
A37: T | B37: ХҮН ХӨЛСЛӨН АЖИЛЛУУЛДАГ ӨРХИЙН ҮЙЛ АЖИЛЛАГАА; ӨРХИЙН ӨӨРИЙН ХЭРЭГЛЭЭНД | C37: 185981.73 | D37: 189401.77 | E37: =D37-C37 | F37: =IFERROR((D37-C37)/C$54*100,"") | G37: =IFERROR(D37/D$54,"") | H37: 188143.89 | I37: 0.637
A38: J | B38: МЭДЭЭЛЭЛ, ХОЛБОО | C38: 128382.22 | D38: 131671.2 | E38: =D38-C38 | F38: =IFERROR((D38-C38)/C$54*100,"") | G38: =IFERROR(D38/D$54,"") | H38: 131666.01 | I38: 0.065
A39: R | B39: УРЛАГ, ҮЗВЭР, ТОГЛООМ НААДАМ | C39: 94451.757 | D39: 97606.089 | E39: =D39-C39 | F39: =IFERROR((D39-C39)/C$54*100,"") | G39: =IFERROR(D39/D$54,"") | H39: 97606.089 | I39: 0.597
A40: Q | B40: ХҮНИЙ ЭРҮҮЛ МЭНД, НИЙГМИЙН ХАЛАМЖИЙН ҮЙЛ АЖИЛЛАГАА | C40: 384882.6 | D40: 387430.24 | E40: =D40-C40 | F40: =IFERROR((D40-C40)/C$54*100,"") | G40: =IFERROR(D40/D$54,"") | H40: 387430.24 | I40: 0.209
A41: M | B41: МЭРГЭЖЛИЙН, ШИНЖЛЭХ УХААН БОЛОН ТЕХНИКИЙН ҮЙЛ АЖИЛЛАГАА | C41: 58871.317 | D41: 58722.832 | E41: =D41-C41 | F41: =IFERROR((D41-C41)/C$54*100,"") | G41: =IFERROR(D41/D$54,"") | H41: 51525.093 | I41: 0.387
A42: O | B42: ТӨРИЙН УДИРДЛАГА, БАТЛАН ХАМГААЛАХ ҮЙЛ АЖИЛЛАГАА, АЛБАН ЖУРМЫН НИЙГМИЙ | C42: 11436.225 | D42: 11057.308 | E42: =D42-C42 | F42: =IFERROR((D42-C42)/C$54*100,"") | G42: =IFERROR(D42/D$54,"") | H42: 11057.308 | I42: 0.054
A43: U | B43: ОЛОН УЛСЫН БАЙГУУЛЛАГА, СУУРИН ТӨЛӨӨЛӨГЧИЙН ҮЙЛ АЖИЛЛАГАА | C43: 32534.359 | D43: 31421.784 | E43: =D43-C43 | F43: =IFERROR((D43-C43)/C$54*100,"") | G43: =IFERROR(D43/D$54,"") | H43: 31421.784 | I43: -0.426
... A53: L | B53: ҮЛ ХӨДЛӨХ ХӨРӨНГИЙН ҮЙЛ АЖИЛЛАГАА | C53: 7819687.9 | D53: 7204175.3 | E53: =D53-C53 | F53: =IFERROR((D53-C53)/C$54*100,"") | G53: =IFERROR(D53/D$54,"") | H53: 7198587.2 | I53: 0.102
...

Sheet Real_Sector
A1: Бодит салбарууд (Real sector — trade, services, construction, industry)
A2: Deck slides 16-21. Source: NSO 1212.mn. Cumulative from the start of the year (өссөн дүнгээр); growth is year on year on that cumulative; each component's contribution is its share of the year-on-year change, so the contributions sum to the headline growth. Money in сая төг.
A4: МЭДЭЭЛЛИЙН ОН САР / DATA AS OF: 2026-06, 2026-07, 2026-Q2 [тайлант үе / reported month: 2026-07] ← ЗАРИМ ХҮСНЭГТ ӨМНӨХ САРЫНХ (some tables lag; each table's own month is on its header line)
A6: Худалдааны салбарын нийт борлуулалт — 2026-06
A7: Сараар, өссөн дүнгээр · нийт 33,813,378.1 сая төг · өмнөх оны мөн үе 30,720,541.5
A8: Бүрэлдэхүүн (Component) | B8: Өмнөх он (Prev, cum.) | C8: Тайлант он (Cur, cum.) | D8: Өөрчлөлт (Change) | E8: Хувь нэмэр (Contribution, pp) | F8: Жилийн өсөлт (YoY)
A9: Улаанбаатар | B9: 26499027 | C9: 29139515 | D9: =C9-B9 | E9: 8.59519 | F9: 0.0996
A10: Төвийн бүс | B10: 2096239.7 | C10: 2364455.7 | D10: =C10-B10 | E10: 0.873084 | F10: 0.128
A11: Хангайн бүс | B11: 1024414.2 | C11: 1144447.8 | D11: =C11-B11 | E11: 0.390727 | F11: 0.1172
A12: Баруун бүс | B12: 587458.34 | C12: 624672.09 | D12: =C12-B12 | E12: 0.121136 | F12: 0.0633
A13: Зүүн бүс | B13: 513402.67 | C13: 540287.03 | D13: =C13-B13 | E13: 0.087513 | F13: 0.0524
A14: Нийт (Total — must equal the headline growth) | B14: =SUM(B9:B13) | C14: =SUM(C9:C13) | D14: =C14-B14 | E14: =SUM(E9:E13) | F14: =IFERROR(C14/B14-1,"")
A15: Салбарын өсөлт (Headline growth, YoY) | E15: 10.0677
A17: Цуваа (series for the chart)
A18: Үе (Period) | B18: Өссөн дүн (Cumulative) | C18: Тухайн үе (Single period)
A19: 2017-01 | B19: 879245.63 | C19: 879245.63
A20: 2017-02 | B20: 1894490.4 | C20: 1015244.8
A21: 2017-03 | B21: 2990107 | C21: 1095616.6
A22: 2017-04 | B22: 4104048.5 | C22: 1113941.5
A23: 2017-05 | B23: 5408122.6 | C23: 1304074.1
A24: 2017-06 | B24: 6861042.3 | C24: 1452919.7
A25: 2017-07 | B25: 8190656.5 | C25: 1329614.2
A26: 2017-08 | B26: 9582407.8 | C26: 1391751.2
A27: 2017-09 | B27: 11073703 | C27: 1491295.1
A28: 2017-10 | B28: 12570370 | C28: 1496667
A29: 2017-11 | B29: 13954734 | C29: 1384364.2
A30: 2017-12 | B30: 15968766 | C30: 2014032.1
... A132: 2026-06 | B132: 33813378 | C132: 6827675.3
A135: Зочид буудлын салбарын орлого — 2026-06
A136: Сараар, өссөн дүнгээр · нийт 154,326.1 сая төг · өмнөх оны мөн үе 137,447.4
A137: Бүрэлдэхүүн (Component) | B137: Өмнөх он (Prev, cum.) | C137: Тайлант он (Cur, cum.) | D137: Өөрчлөлт (Change) | E137: Хувь нэмэр (Contribution, pp) | F137: Жилийн өсөлт (YoY)
A138: Улаанбаатар | B138: 99800.02 | C138: 112244.2 | D138: =C138-B138 | E138: 9.053774 | F138: 0.1247
A139: Төвийн бүс | B139: 13794.73 | C139: 15787.48 | D139: =C139-B139 | E139: 1.449827 | F139: 0.1445
A140: Хангайн бүс | B140: 14970.15 | C140: 16544.05 | D140: =C140-B140 | E140: 1.145092 | F140: 0.1051
A141: Зүүн бүс | B141: 3779.99 | C141: 4305.16 | D141: =C141-B141 | E141: 0.382088 | F141: 0.1389
A142: Баруун бүс | B142: 5102.55 | C142: 5445.2 | D142: =C142-B142 | E142: 0.249295 | F142: 0.0672
A143: Нийт (Total — must equal the headline growth) | B143: =SUM(B138:B142) | C143: =SUM(C138:C142) | D143: =C143-B143 | E143: =SUM(E138:E142) | F143: =IFERROR(C143/B143-1,"")
A144: Салбарын өсөлт (Headline growth, YoY) | E144: 12.2801
A146: Цуваа (series for the chart)
A147: Үе (Period) | B147: Өссөн дүн (Cumulative) | C147: Тухайн үе (Single period)
...

Sheet Sector_Charts
A1: Эдийн засгийн голлох салбаруудын гүйцэтгэл (Performance of the main economic sectors)
A2: Deck slides 16-21. Each chart stacks the components' contributions with the sector's own growth as a line, in the house style. Values are fractions shown as percentages; the contributions in each row sum to that row's growth. Copy a chart straight into the deck, or read the block beneath it. Each chart shows the last three years — change CHART_WINDOW in excel_builder.py for a longer view.
A4: МЭДЭЭЛЛИЙН ОН САР / DATA AS OF: 2026-06, 2026-07, 2026-Q2 [тайлант үе / reported month: 2026-07]
A6: Худалдааны салбарын нийт борлуулалт — 2026-06
A7: Үе (Period) | B7: Улаанбаатар | C7: Төвийн бүс | D7: Хангайн бүс | E7: Баруун бүс | F7: Зүүн бүс | G7: Салбарын өсөлт (Growth) | H7: Нийлбэр (check)
A8: 2023-07 | B8: 0.231076 | C8: 0.01898 | D8: 0.005965 | E8: 0.003403 | F8: 0.004394 | G8: 0.263818 | H8: =ROUND(SUM(B8:F8)-G8,5)
A9: 2023-08 | B9: 0.229299 | C9: 0.018741 | D9: 0.005779 | E9: 0.003515 | F9: 0.004237 | G9: 0.261571 | H9: =ROUND(SUM(B9:F9)-G9,5)
A10: 2023-09 | B10: 0.210895 | C10: 0.018924 | D10: 0.005726 | E10: 0.0035 | F10: 0.004417 | G10: 0.243462 | H10: =ROUND(SUM(B10:F10)-G10,5)
A11: 2023-10 | B11: 0.206203 | C11: 0.01857 | D11: 0.006006 | E11: 0.003528 | F11: 0.004597 | G11: 0.238904 | H11: =ROUND(SUM(B11:F11)-G11,5)
A12: 2023-11 | B12: 0.203593 | C12: 0.017747 | D12: 0.005932 | E12: 0.003422 | F12: 0.00453 | G12: 0.235223 | H12: =ROUND(SUM(B12:F12)-G12,5)
A13: 2023-12 | B13: 0.202206 | C13: 0.01662 | D13: 0.0062 | E13: 0.003362 | F13: 0.004345 | G13: 0.232734 | H13: =ROUND(SUM(B13:F13)-G13,5)
A14: 2024-01 | B14: 0.207924 | C14: 0.008054 | D14: 0.007297 | E14: 0.00449 | F14: 0.005534 | G14: 0.233298 | H14: =ROUND(SUM(B14:F14)-G14,5)
A15: 2024-02 | B15: 0.184907 | C15: 0.009175 | D15: 0.004521 | E15: 0.003919 | F15: 0.002942 | G15: 0.205465 | H15: =ROUND(SUM(B15:F15)-G15,5)
A16: 2024-03 | B16: 0.172224 | C16: 0.009478 | D16: 0.00138 | E16: 0.003205 | F16: 0.002366 | G16: 0.188653 | H16: =ROUND(SUM(B16:F16)-G16,5)
A17: 2024-04 | B17: 0.18392 | C17: 0.010149 | D17: 0.003375 | E17: 0.003003 | F17: 0.002297 | G17: 0.202744 | H17: =ROUND(SUM(B17:F17)-G17,5)
A18: 2024-05 | B18: 0.176408 | C18: 0.009661 | D18: 0.003495 | E18: 0.002949 | F18: 0.002679 | G18: 0.195192 | H18: =ROUND(SUM(B18:F18)-G18,5)
A19: 2024-06 | B19: 0.144887 | C19: 0.009124 | D19: 0.003486 | E19: 0.003204 | F19: 0.002635 | G19: 0.163336 | H19: =ROUND(SUM(B19:F19)-G19,5)
... A43: 2026-06 | B43: 0.085952 | C43: 0.008731 | D43: 0.003907 | E43: 0.001211 | F43: 0.000875 | G43: 0.100677 | H43: =ROUND(SUM(B43:F43)-G43,5)
A44: Шалгалт: сүүлийн багана бүх мөрөнд 0 байх ёстой (the check column must read 0 on every row — the bars stack up to the line)
A67: Зочид буудлын салбарын орлого — 2026-06
A68: Үе (Period) | B68: Улаанбаатар | C68: Төвийн бүс | D68: Хангайн бүс | E68: Зүүн бүс | F68: Баруун бүс | G68: Салбарын өсөлт (Growth) | H68: Нийлбэр (check)
